[2024-07-19 17:18:11,504: INFO/MainProcess] beat: Starting...
[2024-07-19 17:18:11,512: ERROR/MainProcess] Removing corrupted schedule file 'celerybeat-schedule': error(11, 'Resource temporarily unavailable')
Traceback (most recent call last):
  File "/usr/local/lib/python3.10/site-packages/celery/beat.py", line 531, in setup_schedule
    self._store = self._open_schedule()
  File "/usr/local/lib/python3.10/site-packages/celery/beat.py", line 521, in _open_schedule
    return self.persistence.open(self.schedule_filename, writeback=True)
  File "/usr/local/lib/python3.10/shelve.py", line 243, in open
    return DbfilenameShelf(filename, flag, protocol, writeback)
  File "/usr/local/lib/python3.10/shelve.py", line 227, in __init__
    Shelf.__init__(self, dbm.open(filename, flag), protocol, writeback)
  File "/usr/local/lib/python3.10/dbm/__init__.py", line 95, in open
    return mod.open(file, flag, mode)
_gdbm.error: [Errno 11] Resource temporarily unavailable: 'celerybeat-schedule'
[2024-07-19 17:19:00,076: INFO/MainProcess] Scheduler: Sending due task every-30-minutes (celery_object.before_dawn)
